Workbook

Sheet Zomato Sales
A1: Order ID | B1: Store ID | C1: Order Date | D1: Cuisine | E1: Category | F1: Quantity | G1: Price per Item | H1: Discount % | I1: Sales Amount | J1: Delivery Time (min) | K1: Rating | L1: Payment Mode | M1: Store Name (Explicit Ref) | N1: Store City (Structured Ref) | O1: Rating Category (Nested IF) | P1: Order Size Tag (AND/OR) | Q1: Price per Rating Pt (IFERROR)
A2: ORD1001 | B2: STR05 | C2: 45720 | D2: Italian | E2: Veg | F2: 6 | G2: 129 | H2: 0.2 | I2: =F2*G2*(1-H2) -> 619.2 | J2: 20 | K2: 2.1 | L2: Wallet | M2: =INDEX(Stores!$B$2:$B$13,MATCH(B2,Stores!$A$2:$A$13,0)) -> Zomato - Hyderabad Store | N2: =INDEX(StoresTbl[City],MATCH(B2,StoresTbl[Store ID],0)) -> Hyderabad | O2: =IF(K2="","Not Rated",IF(K2>=4.5,"Excellent",IF(K2>=3.5,"Good",IF(K2>=2.5,"Average","Poor")))) -> Poor | P2: =IF(AND(F2>=3,H2>=0.1),"Bulk & Discounted",IF(OR(F2>=5,I2>800),"Large Order","Standard Order")) -> Bulk & Discounted | Q2: =IFERROR(G2/K2,"No Rating Yet") -> 61.428571
A3: ORD1002 | B3: STR02 | C3: 45713 | D3: Italian | E3: Veg | F3: 5 | G3: 179 | H3: 0.2 | I3: =F3*G3*(1-H3) -> 716 | J3: 41 | L3: Card | M3: =INDEX(Stores!$B$2:$B$13,MATCH(B3,Stores!$A$2:$A$13,0)) -> Zomato - Delhi Store | N3: =INDEX(StoresTbl[City],MATCH(B3,StoresTbl[Store ID],0)) -> Delhi | O3: =IF(K3="","Not Rated",IF(K3>=4.5,"Excellent",IF(K3>=3.5,"Good",IF(K3>=2.5,"Average","Poor")))) -> Not Rated | P3: =IF(AND(F3>=3,H3>=0.1),"Bulk & Discounted",IF(OR(F3>=5,I3>800),"Large Order","Standard Order")) -> Bulk & Discounted | Q3: =IFERROR(G3/K3,"No Rating Yet") -> No Rating Yet
A4: ORD1003 | B4: STR08 | C4: 45808 | D4: Fast Food | E4: Veg | F4: 2 | G4: 449 | H4: 0.15 | I4: =F4*G4*(1-H4) -> 763.3 | J4: 36 | K4: 2.5 | L4: Cash | M4: =INDEX(Stores!$B$2:$B$13,MATCH(B4,Stores!$A$2:$A$13,0)) -> Zomato - Ahmedabad Store | N4: =INDEX(StoresTbl[City],MATCH(B4,StoresTbl[Store ID],0)) -> Ahmedabad | O4: =IF(K4="","Not Rated",IF(K4>=4.5,"Excellent",IF(K4>=3.5,"Good",IF(K4>=2.5,"Average","Poor")))) -> Average | P4: =IF(AND(F4>=3,H4>=0.1),"Bulk & Discounted",IF(OR(F4>=5,I4>800),"Large Order","Standard Order")) -> Standard Order | Q4: =IFERROR(G4/K4,"No Rating Yet") -> 179.6
A5: ORD1004 | B5: STR06 | C5: 45684 | D5: South Indian | E5: Non-Veg | F5: 1 | G5: 229 | H5: 0.1 | I5: =F5*G5*(1-H5) -> 206.1 | J5: 53 | K5: 4.4 | L5: Cash | M5: =INDEX(Stores!$B$2:$B$13,MATCH(B5,Stores!$A$2:$A$13,0)) -> Zomato - Chennai Store | N5: =INDEX(StoresTbl[City],MATCH(B5,StoresTbl[Store ID],0)) -> Chennai | O5: =IF(K5="","Not Rated",IF(K5>=4.5,"Excellent",IF(K5>=3.5,"Good",IF(K5>=2.5,"Average","Poor")))) -> Good | P5: =IF(AND(F5>=3,H5>=0.1),"Bulk & Discounted",IF(OR(F5>=5,I5>800),"Large Order","Standard Order")) -> Standard Order | Q5: =IFERROR(G5/K5,"No Rating Yet") -> 52.045455
A6: ORD1005 | B6: STR12 | C6: 45775 | D6: Mughlai | E6: Veg | F6: 4 | G6: 129 | H6: 0.2 | I6: =F6*G6*(1-H6) -> 412.8 | J6: 33 | K6: 3.7 | L6: Cash | M6: =INDEX(Stores!$B$2:$B$13,MATCH(B6,Stores!$A$2:$A$13,0)) -> Zomato - Indore Store | N6: =INDEX(StoresTbl[City],MATCH(B6,StoresTbl[Store ID],0)) -> Indore | O6: =IF(K6="","Not Rated",IF(K6>=4.5,"Excellent",IF(K6>=3.5,"Good",IF(K6>=2.5,"Average","Poor")))) -> Good | P6: =IF(AND(F6>=3,H6>=0.1),"Bulk & Discounted",IF(OR(F6>=5,I6>800),"Large Order","Standard Order")) -> Bulk & Discounted | Q6: =IFERROR(G6/K6,"No Rating Yet") -> 34.864865
A7: ORD1006 | B7: STR12 | C7: 45675 | D7: North Indian | E7: Veg | F7: 3 | G7: 129 | H7: 0.05 | I7: =F7*G7*(1-H7) -> 367.65 | J7: 21 | K7: 2.8 | L7: Wallet | M7: =INDEX(Stores!$B$2:$B$13,MATCH(B7,Stores!$A$2:$A$13,0)) -> Zomato - Indore Store | N7: =INDEX(StoresTbl[City],MATCH(B7,StoresTbl[Store ID],0)) -> Indore | O7: =IF(K7="","Not Rated",IF(K7>=4.5,"Excellent",IF(K7>=3.5,"Good",IF(K7>=2.5,"Average","Poor")))) -> Average | P7: =IF(AND(F7>=3,H7>=0.1),"Bulk & Discounted",IF(OR(F7>=5,I7>800),"Large Order","Standard Order")) -> Standard Order | Q7: =IFERROR(G7/K7,"No Rating Yet") -> 46.071429
A8: ORD1007 | B8: STR11 | C8: 45751 | D8: Chinese | E8: Non-Veg | F8: 3 | G8: 179 | H8: 0.1 | I8: =F8*G8*(1-H8) -> 483.3 | J8: 19 | K8: 3.6 | L8: Card | M8: =INDEX(Stores!$B$2:$B$13,MATCH(B8,Stores!$A$2:$A$13,0)) -> Zomato - Chandigarh Store | N8: =INDEX(StoresTbl[City],MATCH(B8,StoresTbl[Store ID],0)) -> Chandigarh | O8: =IF(K8="","Not Rated",IF(K8>=4.5,"Excellent",IF(K8>=3.5,"Good",IF(K8>=2.5,"Average","Poor")))) -> Good | P8: =IF(AND(F8>=3,H8>=0.1),"Bulk & Discounted",IF(OR(F8>=5,I8>800),"Large Order","Standard Order")) -> Bulk & Discounted | Q8: =IFERROR(G8/K8,"No Rating Yet") -> 49.722222
A9: ORD1008 | B9: STR04 | C9: 45699 | D9: Beverages | E9: Non-Veg | F9: 3 | G9: 399 | H9: 0.2 | I9: =F9*G9*(1-H9) -> 957.6 | J9: 29 | L9: Cash | M9: =INDEX(Stores!$B$2:$B$13,MATCH(B9,Stores!$A$2:$A$13,0)) -> Zomato - Pune Store | N9: =INDEX(StoresTbl[City],MATCH(B9,StoresTbl[Store ID],0)) -> Pune | O9: =IF(K9="","Not Rated",IF(K9>=4.5,"Excellent",IF(K9>=3.5,"Good",IF(K9>=2.5,"Average","Poor")))) -> Not Rated | P9: =IF(AND(F9>=3,H9>=0.1),"Bulk & Discounted",IF(OR(F9>=5,I9>800),"Large Order","Standard Order")) -> Bulk & Discounted | Q9: =IFERROR(G9/K9,"No Rating Yet") -> No Rating Yet
A10: ORD1009 | B10: STR01 | C10: 45716 | D10: North Indian | E10: Non-Veg | F10: 4 | G10: 199 | H10: 0 | I10: =F10*G10*(1-H10) -> 796 | J10: 28 | K10: 2.6 | L10: Cash | M10: =INDEX(Stores!$B$2:$B$13,MATCH(B10,Stores!$A$2:$A$13,0)) -> Zomato - Mumbai Store | N10: =INDEX(StoresTbl[City],MATCH(B10,StoresTbl[Store ID],0)) -> Mumbai | O10: =IF(K10="","Not Rated",IF(K10>=4.5,"Excellent",IF(K10>=3.5,"Good",IF(K10>=2.5,"Average","Poor")))) -> Average | P10: =IF(AND(F10>=3,H10>=0.1),"Bulk & Discounted",IF(OR(F10>=5,I10>800),"Large Order","Standard Order")) -> Standard Order | Q10: =IFERROR(G10/K10,"No Rating Yet") -> 76.538462
A11: ORD1010 | B11: STR08 | C11: 45759 | D11: Beverages | E11: Veg | F11: 3 | G11: 149 | H11: 0.05 | I11: =F11*G11*(1-H11) -> 424.65 | J11: 50 | K11: 4.2 | L11: Cash | M11: =INDEX(Stores!$B$2:$B$13,MATCH(B11,Stores!$A$2:$A$13,0)) -> Zomato - Ahmedabad Store | N11: =INDEX(StoresTbl[City],MATCH(B11,StoresTbl[Store ID],0)) -> Ahmedabad | O11: =IF(K11="","Not Rated",IF(K11>=4.5,"Excellent",IF(K11>=3.5,"Good",IF(K11>=2.5,"Average","Poor")))) -> Good | P11: =IF(AND(F11>=3,H11>=0.1),"Bulk & Discounted",IF(OR(F11>=5,I11>800),"Large Order","Standard Order")) -> Standard Order | Q11: =IFERROR(G11/K11,"No Rating Yet") -> 35.47619
A12: ORD1011 | B12: STR07 | C12: 45807 | D12: Desserts | E12: Non-Veg | F12: 2 | G12: 149 | H12: 0.2 | I12: =F12*G12*(1-H12) -> 238.4 | J12: 46 | K12: 4.3 | L12: UPI | M12: =INDEX(Stores!$B$2:$B$13,MATCH(B12,Stores!$A$2:$A$13,0)) -> Zomato - Kolkata Store | N12: =INDEX(StoresTbl[City],MATCH(B12,StoresTbl[Store ID],0)) -> Kolkata | O12: =IF(K12="","Not Rated",IF(K12>=4.5,"Excellent",IF(K12>=3.5,"Good",IF(K12>=2.5,"Average","Poor")))) -> Good | P12: =IF(AND(F12>=3,H12>=0.1),"Bulk & Discounted",IF(OR(F12>=5,I12>800),"Large Order","Standard Order")) -> Standard Order | Q12: =IFERROR(G12/K12,"No Rating Yet") -> 34.651163
A13: ORD1012 | B13: STR02 | C13: 45697 | D13: Chinese | E13: Non-Veg | F13: 5 | G13: 129 | H13: 0.15 | I13: =F13*G13*(1-H13) -> 548.25 | J13: 39 | K13: 3.6 | L13: Wallet | M13: =INDEX(Stores!$B$2:$B$13,MATCH(B13,Stores!$A$2:$A$13,0)) -> Zomato - Delhi Store | N13: =INDEX(StoresTbl[City],MATCH(B13,StoresTbl[Store ID],0)) -> Delhi | O13: =IF(K13="","Not Rated",IF(K13>=4.5,"Excellent",IF(K13>=3.5,"Good",IF(K13>=2.5,"Average","Poor")))) -> Good | P13: =IF(AND(F13>=3,H13>=0.1),"Bulk & Discounted",IF(OR(F13>=5,I13>800),"Large Order","Standard Order")) -> Bulk & Discounted | Q13: =IFERROR(G13/K13,"No Rating Yet") -> 35.833333
A14: ORD1013 | B14: STR09 | C14: 45660 | D14: South Indian | E14: Non-Veg | F14: 6 | G14: 229 | H14: 0 | I14: =F14*G14*(1-H14) -> 1374 | J14: 33 | K14: 2.5 | L14: Wallet | M14: =INDEX(Stores!$B$2:$B$13,MATCH(B14,Stores!$A$2:$A$13,0)) -> Zomato - Jaipur Store | N14: =INDEX(StoresTbl[City],MATCH(B14,StoresTbl[Store ID],0)) -> Jaipur | O14: =IF(K14="","Not Rated",IF(K14>=4.5,"Excellent",IF(K14>=3.5,"Good",IF(K14>=2.5,"Average","Poor")))) -> Average | P14: =IF(AND(F14>=3,H14>=0.1),"Bulk & Discounted",IF(OR(F14>=5,I14>800),"Large Order","Standard Order")) -> Large Order | Q14: =IFERROR(G14/K14,"No Rating Yet") -> 91.6
A15: ORD1014 | B15: STR01 | C15: 45725 | D15: Mughlai | E15: Veg | F15: 5 | G15: 129 | H15: 0.1 | I15: =F15*G15*(1-H15) -> 580.5 | J15: 55 | K15: 2.5 | L15: Card | M15: =INDEX(Stores!$B$2:$B$13,MATCH(B15,Stores!$A$2:$A$13,0)) -> Zomato - Mumbai Store | N15: =INDEX(StoresTbl[City],MATCH(B15,StoresTbl[Store ID],0)) -> Mumbai | O15: =IF(K15="","Not Rated",IF(K15>=4.5,"Excellent",IF(K15>=3.5,"Good",IF(K15>=2.5,"Average","Poor")))) -> Average | P15: =IF(AND(F15>=3,H15>=0.1),"Bulk & Discounted",IF(OR(F15>=5,I15>800),"Large Order","Standard Order")) -> Bulk & Discounted | Q15: =IFERROR(G15/K15,"No Rating Yet") -> 51.6
A16: ORD1015 | B16: STR03 | C16: 45796 | D16: Mughlai | E16: Veg | F16: 5 | G16: 229 | H16: 0.15 | I16: =F16*G16*(1-H16) -> 973.25 | J16: 16 | K16: 4.8 | L16: UPI | M16: =INDEX(Stores!$B$2:$B$13,MATCH(B16,Stores!$A$2:$A$13,0)) -> Zomato - Bangalore Store | N16: =INDEX(StoresTbl[City],MATCH(B16,StoresTbl[Store ID],0)) -> Bangalore | O16: =IF(K16="","Not Rated",IF(K16>=4.5,"Excellent",IF(K16>=3.5,"Good",IF(K16>=2.5,"Average","Poor")))) -> Excellent | P16: =IF(AND(F16>=3,H16>=0.1),"Bulk & Discounted",IF(OR(F16>=5,I16>800),"Large Order","Standard Order")) -> Bulk & Discounted | Q16: =IFERROR(G16/K16,"No Rating Yet") -> 47.708333
A17: ORD1016 | B17: STR05 | C17: 45719 | D17: North Indian | E17: Veg | F17: 5 | G17: 129 | H17: 0 | I17: =F17*G17*(1-H17) -> 645 | J17: 46 | K17: 4.9 | L17: UPI | M17: =INDEX(Stores!$B$2:$B$13,MATCH(B17,Stores!$A$2:$A$13,0)) -> Zomato - Hyderabad Store | N17: =INDEX(StoresTbl[City],MATCH(B17,StoresTbl[Store ID],0)) -> Hyderabad | O17: =IF(K17="","Not Rated",IF(K17>=4.5,"Excellent",IF(K17>=3.5,"Good",IF(K17>=2.5,"Average","Poor")))) -> Excellent | P17: =IF(AND(F17>=3,H17>=0.1),"Bulk & Discounted",IF(OR(F17>=5,I17>800),"Large Order","Standard Order")) -> Large Order | Q17: =IFERROR(G17/K17,"No Rating Yet") -> 26.326531
A18: ORD1017 | B18: STR09 | C18: 45690 | D18: Chinese | E18: Non-Veg | F18: 5 | G18: 149 | H18: 0.1 | I18: =F18*G18*(1-H18) -> 670.5 | J18: 48 | K18: 4.9 | L18: Wallet | M18: =INDEX(Stores!$B$2:$B$13,MATCH(B18,Stores!$A$2:$A$13,0)) -> Zomato - Jaipur Store | N18: =INDEX(StoresTbl[City],MATCH(B18,StoresTbl[Store ID],0)) -> Jaipur | O18: =IF(K18="","Not Rated",IF(K18>=4.5,"Excellent",IF(K18>=3.5,"Good",IF(K18>=2.5,"Average","Poor")))) -> Excellent | P18: =IF(AND(F18>=3,H18>=0.1),"Bulk & Discounted",IF(OR(F18>=5,I18>800),"Large Order","Standard Order")) -> Bulk & Discounted | Q18: =IFERROR(G18/K18,"No Rating Yet") -> 30.408163
A19: ORD1018 | B19: STR09 | C19: 45834 | D19: Italian | E19: Non-Veg | F19: 4 | G19: 399 | H19: 0.1 | I19: =F19*G19*(1-H19) -> 1436.4 | J19: 43 | K19: 2.4 | L19: Wallet | M19: =INDEX(Stores!$B$2:$B$13,MATCH(B19,Stores!$A$2:$A$13,0)) -> Zomato - Jaipur Store | N19: =INDEX(StoresTbl[City],MATCH(B19,StoresTbl[Store ID],0)) -> Jaipur | O19: =IF(K19="","Not Rated",IF(K19>=4.5,"Excellent",IF(K19>=3.5,"Good",IF(K19>=2.5,"Average","Poor")))) -> Poor | P19: =IF(AND(F19>=3,H19>=0.1),"Bulk & Discounted",IF(OR(F19>=5,I19>800),"Large Order","Standard Order")) -> Bulk & Discounted | Q19: =IFERROR(G19/K19,"No Rating Yet") -> 166.25
A20: ORD1019 | B20: STR04 | C20: 45674 | D20: Biryani | E20: Veg | F20: 5 | G20: 299 | H20: 0.05 | I20: =F20*G20*(1-H20) -> 1420.25 | J20: 52 | K20: 2 | L20: Card | M20: =INDEX(Stores!$B$2:$B$13,MATCH(B20,Stores!$A$2:$A$13,0)) -> Zomato - Pune Store | N20: =INDEX(StoresTbl[City],MATCH(B20,StoresTbl[Store ID],0)) -> Pune | O20: =IF(K20="","Not Rated",IF(K20>=4.5,"Excellent",IF(K20>=3.5,"Good",IF(K20>=2.5,"Average","Poor")))) -> Poor | P20: =IF(AND(F20>=3,H20>=0.1),"Bulk & Discounted",IF(OR(F20>=5,I20>800),"Large Order","Standard Order")) -> Large Order | Q20: =IFERROR(G20/K20,"No Rating Yet") -> 149.5
A21: ORD1020 | B21: STR12 | C21: 45819 | D21: North Indian | E21: Veg | F21: 1 | G21: 99 | H21: 0.1 | I21: =F21*G21*(1-H21) -> 89.1 | J21: 19 | K21: 2.8 | L21: Card | M21: =INDEX(Stores!$B$2:$B$13,MATCH(B21,Stores!$A$2:$A$13,0)) -> Zomato - Indore Store | N21: =INDEX(StoresTbl[City],MATCH(B21,StoresTbl[Store ID],0)) -> Indore | O21: =IF(K21="","Not Rated",IF(K21>=4.5,"Excellent",IF(K21>=3.5,"Good",IF(K21>=2.5,"Average","Poor")))) -> Average | P21: =IF(AND(F21>=3,H21>=0.1),"Bulk & Discounted",IF(OR(F21>=5,I21>800),"Large Order","Standard Order")) -> Standard Order | Q21: =IFERROR(G21/K21,"No Rating Yet") -> 35.357143
... A41: ORD1040 | B41: STR04 | C41: 45699 | D41: Chinese | E41: Non-Veg | F41: 1 | G41: 149 | H41: 0.1 | I41: =F41*G41*(1-H41) -> 134.1 | J41: 41 | K41: 2.8 | L41: Card | M41: =INDEX(Stores!$B$2:$B$13,MATCH(B41,Stores!$A$2:$A$13,0)) -> Zomato - Pune Store | N41: =INDEX(StoresTbl[City],MATCH(B41,StoresTbl[Store ID],0)) -> Pune | O41: =IF(K41="","Not Rated",IF(K41>=4.5,"Excellent",IF(K41>=3.5,"Good",IF(K41>=2.5,"Average","Poor")))) -> Average | P41: =IF(AND(F41>=3,H41>=0.1),"Bulk & Discounted",IF(OR(F41>=5,I41>800),"Large Order","Standard Order")) -> Standard Order | Q41: =IFERROR(G41/K41,"No Rating Yet") -> 53.214286
A42: ORD1041 | B42: STR12 | C42: 45685 | D42: Desserts | E42: Veg | F42: 4 | G42: 179 | H42: 0.05 | I42: =F42*G42*(1-H42) -> 680.2 | J42: 44 | L42: Cash | M42: =INDEX(Stores!$B$2:$B$13,MATCH(B42,Stores!$A$2:$A$13,0)) -> Zomato - Indore Store | N42: =INDEX(StoresTbl[City],MATCH(B42,StoresTbl[Store ID],0)) -> Indore | O42: =IF(K42="","Not Rated",IF(K42>=4.5,"Excellent",IF(K42>=3.5,"Good",IF(K42>=2.5,"Average","Poor")))) -> Not Rated | P42: =IF(AND(F42>=3,H42>=0.1),"Bulk & Discounted",IF(OR(F42>=5,I42>800),"Large Order","Standard Order")) -> Standard Order | Q42: =IFERROR(G42/K42,"No Rating Yet") -> No Rating Yet
A43: ORD1042 | B43: STR05 | C43: 45716 | D43: Italian | E43: Veg | F43: 6 | G43: 179 | H43: 0.15 | I43: =F43*G43*(1-H43) -> 912.9 | J43: 36 | K43: 4.6 | L43: Cash | M43: =INDEX(Stores!$B$2:$B$13,MATCH(B43,Stores!$A$2:$A$13,0)) -> Zomato - Hyderabad Store | N43: =INDEX(StoresTbl[City],MATCH(B43,StoresTbl[Store ID],0)) -> Hyderabad | O43: =IF(K43="","Not Rated",IF(K43>=4.5,"Excellent",IF(K43>=3.5,"Good",IF(K43>=2.5,"Average","Poor")))) -> Excellent | P43: =IF(AND(F43>=3,H43>=0.1),"Bulk & Discounted",IF(OR(F43>=5,I43>800),"Large Order","Standard Order")) -> Bulk & Discounted | Q43: =IFERROR(G43/K43,"No Rating Yet") -> 38.913043
A44: ORD1043 | B44: STR05 | C44: 45747 | D44: Mughlai | E44: Non-Veg | F44: 6 | G44: 299 | H44: 0.1 | I44: =F44*G44*(1-H44) -> 1614.6 | J44: 16 | K44: 4.6 | L44: UPI | M44: =INDEX(Stores!$B$2:$B$13,MATCH(B44,Stores!$A$2:$A$13,0)) -> Zomato - Hyderabad Store | N44: =INDEX(StoresTbl[City],MATCH(B44,StoresTbl[Store ID],0)) -> Hyderabad | O44: =IF(K44="","Not Rated",IF(K44>=4.5,"Excellent",IF(K44>=3.5,"Good",IF(K44>=2.5,"Average","Poor")))) -> Excellent | P44: =IF(AND(F44>=3,H44>=0.1),"Bulk & Discounted",IF(OR(F44>=5,I44>800),"Large Order","Standard Order")) -> Bulk & Discounted | Q44: =IFERROR(G44/K44,"No Rating Yet") -> 65
A45: ORD1044 | B45: STR05 | C45: 45703 | D45: Continental | E45: Non-Veg | F45: 1 | G45: 129 | H45: 0.2 | I45: =F45*G45*(1-H45) -> 103.2 | J45: 42 | K45: 4.2 | L45: Cash | M45: =INDEX(Stores!$B$2:$B$13,MATCH(B45,Stores!$A$2:$A$13,0)) -> Zomato - Hyderabad Store | N45: =INDEX(StoresTbl[City],MATCH(B45,StoresTbl[Store ID],0)) -> Hyderabad | O45: =IF(K45="","Not Rated",IF(K45>=4.5,"Excellent",IF(K45>=3.5,"Good",IF(K45>=2.5,"Average","Poor")))) -> Good | P45: =IF(AND(F45>=3,H45>=0.1),"Bulk & Discounted",IF(OR(F45>=5,I45>800),"Large Order","Standard Order")) -> Standard Order | Q45: =IFERROR(G45/K45,"No Rating Yet") -> 30.714286
A46: ORD1045 | B46: STR06 | C46: 45769 | D46: Continental | E46: Veg | F46: 4 | G46: 349 | H46: 0.05 | I46: =F46*G46*(1-H46) -> 1326.2 | J46: 31 | K46: 4.1 | L46: UPI | M46: =INDEX(Stores!$B$2:$B$13,MATCH(B46,Stores!$A$2:$A$13,0)) -> Zomato - Chennai Store | N46: =INDEX(StoresTbl[City],MATCH(B46,StoresTbl[Store ID],0)) -> Chennai | O46: =IF(K46="","Not Rated",IF(K46>=4.5,"Excellent",IF(K46>=3.5,"Good",IF(K46>=2.5,"Average","Poor")))) -> Good | P46: =IF(AND(F46>=3,H46>=0.1),"Bulk & Discounted",IF(OR(F46>=5,I46>800),"Large Order","Standard Order")) -> Large Order | Q46: =IFERROR(G46/K46,"No Rating Yet") -> 85.121951
A47: ORD1046 | B47: STR01 | C47: 45791 | D47: Mughlai | E47: Veg | F47: 3 | G47: 249 | H47: 0 | I47: =F47*G47*(1-H47) -> 747 | J47: 36 | K47: 4 | L47: Cash | M47: =INDEX(Stores!$B$2:$B$13,MATCH(B47,Stores!$A$2:$A$13,0)) -> Zomato - Mumbai Store | N47: =INDEX(StoresTbl[City],MATCH(B47,StoresTbl[Store ID],0)) -> Mumbai | O47: =IF(K47="","Not Rated",IF(K47>=4.5,"Excellent",IF(K47>=3.5,"Good",IF(K47>=2.5,"Average","Poor")))) -> Good | P47: =IF(AND(F47>=3,H47>=0.1),"Bulk & Discounted",IF(OR(F47>=5,I47>800),"Large Order","Standard Order")) -> Standard Order | Q47: =IFERROR(G47/K47,"No Rating Yet") -> 62.25
A48: ORD1047 | B48: STR02 | C48: 45734 | D48: Mughlai | E48: Non-Veg | F48: 6 | G48: 249 | H48: 0.1 | I48: =F48*G48*(1-H48) -> 1344.6 | J48: 40 | K48: 3.7 | L48: Cash | M48: =INDEX(Stores!$B$2:$B$13,MATCH(B48,Stores!$A$2:$A$13,0)) -> Zomato - Delhi Store | N48: =INDEX(StoresTbl[City],MATCH(B48,StoresTbl[Store ID],0)) -> Delhi | O48: =IF(K48="","Not Rated",IF(K48>=4.5,"Excellent",IF(K48>=3.5,"Good",IF(K48>=2.5,"Average","Poor")))) -> Good | P48: =IF(AND(F48>=3,H48>=0.1),"Bulk & Discounted",IF(OR(F48>=5,I48>800),"Large Order","Standard Order")) -> Bulk & Discounted | Q48: =IFERROR(G48/K48,"No Rating Yet") -> 67.297297
A49: ORD1048 | B49: STR04 | C49: 45765 | D49: Desserts | E49: Veg | F49: 5 | G49: 349 | H49: 0.1 | I49: =F49*G49*(1-H49) -> 1570.5 | J49: 40 | L49: UPI | M49: =INDEX(Stores!$B$2:$B$13,MATCH(B49,Stores!$A$2:$A$13,0)) -> Zomato - Pune Store | N49: =INDEX(StoresTbl[City],MATCH(B49,StoresTbl[Store ID],0)) -> Pune | O49: =IF(K49="","Not Rated",IF(K49>=4.5,"Excellent",IF(K49>=3.5,"Good",IF(K49>=2.5,"Average","Poor")))) -> Not Rated | P49: =IF(AND(F49>=3,H49>=0.1),"Bulk & Discounted",IF(OR(F49>=5,I49>800),"Large Order","Standard Order")) -> Bulk & Discounted | Q49: =IFERROR(G49/K49,"No Rating Yet") -> No Rating Yet
A50: ORD1049 | B50: STR05 | C50: 45731 | D50: Italian | E50: Non-Veg | F50: 5 | G50: 349 | H50: 0.1 | I50: =F50*G50*(1-H50) -> 1570.5 | J50: 44 | K50: 3.3 | L50: Wallet | M50: =INDEX(Stores!$B$2:$B$13,MATCH(B50,Stores!$A$2:$A$13,0)) -> Zomato - Hyderabad Store | N50: =INDEX(StoresTbl[City],MATCH(B50,StoresTbl[Store ID],0)) -> Hyderabad | O50: =IF(K50="","Not Rated",IF(K50>=4.5,"Excellent",IF(K50>=3.5,"Good",IF(K50>=2.5,"Average","Poor")))) -> Average | P50: =IF(AND(F50>=3,H50>=0.1),"Bulk & Discounted",IF(OR(F50>=5,I50>800),"Large Order","Standard Order")) -> Bulk & Discounted | Q50: =IFERROR(G50/K50,"No Rating Yet") -> 105.75758
A51: ORD1050 | B51: STR04 | C51: 45788 | D51: Beverages | E51: Veg | F51: 6 | G51: 129 | H51: 0.1 | I51: =F51*G51*(1-H51) -> 696.6 | J51: 47 | K51: 2.3 | L51: Cash | M51: =INDEX(Stores!$B$2:$B$13,MATCH(B51,Stores!$A$2:$A$13,0)) -> Zomato - Pune Store | N51: =INDEX(StoresTbl[City],MATCH(B51,StoresTbl[Store ID],0)) -> Pune | O51: =IF(K51="","Not Rated",IF(K51>=4.5,"Excellent",IF(K51>=3.5,"Good",IF(K51>=2.5,"Average","Poor")))) -> Poor | P51: =IF(AND(F51>=3,H51>=0.1),"Bulk & Discounted",IF(OR(F51>=5,I51>800),"Large Order","Standard Order")) -> Bulk & Discounted | Q51: =IFERROR(G51/K51,"No Rating Yet") -> 56.086957
A54: FORMULA LEARNING ZONE - Zomato Sales Data
A56: 1. EXPLICIT vs STRUCTURED REFERENCES
A57: Explicit references point to fixed cell ranges (A2:A51). Structured references point to Table column names (TableName[Column]) and auto-expand when rows are added.
A59: Description | C59: Reference Type | D59: Formula | F59: Result
A60: Total Sales Amount | C60: Explicit Reference | D60: =SUM(I2:I51) | F60: =SUM(I2:I51) -> 41494.05
A61: Total Sales Amount | C61: Structured Reference | D61: =SUM(ZomatoSalesTbl[Sales Amount]) | F61: =SUM(ZomatoSalesTbl[Sales Amount]) -> 41494.05
A62: Average Quantity per Order | C62: Explicit Reference | D62: =AVERAGE(F2:F51) | F62: =AVERAGE(F2:F51) -> 3.8
A63: Average Quantity per Order | C63: Structured Reference | D63: =AVERAGE(ZomatoSalesTbl[Quantity]) | F63: =AVERAGE(ZomatoSalesTbl[Quantity]) -> 3.8
...

Sheet Stores
A1: Store ID | B1: Store Name | C1: City | D1: Region | E1: Manager Name | F1: Store Type | G1: Onboarded Year
A2: STR01 | B2: Zomato - Mumbai Store | C2: Mumbai | D2: West | E2: Rohan Mehta | F2: Cloud Kitchen | G2: 2019
A3: STR02 | B3: Zomato - Delhi Store | C3: Delhi | D3: North | E3: Priya Sharma | F3: Dine-in | G3: 2020
A4: STR03 | B4: Zomato - Bangalore Store | C4: Bangalore | D4: South | E4: Aditya Rao | F4: Both | G4: 2021
A5: STR04 | B5: Zomato - Pune Store | C5: Pune | D5: West | E5: Sneha Kulkarni | F5: Cloud Kitchen | G5: 2018
A6: STR05 | B6: Zomato - Hyderabad Store | C6: Hyderabad | D6: South | E6: Kabir Singh | F6: Both | G6: 2022
A7: STR06 | B7: Zomato - Chennai Store | C7: Chennai | D7: South | E7: Anjali Nair | F7: Dine-in | G7: 2020
A8: STR07 | B8: Zomato - Kolkata Store | C8: Kolkata | D8: East | E8: Vikram Joshi | F8: Cloud Kitchen | G8: 2021
A9: STR08 | B9: Zomato - Ahmedabad Store | C9: Ahmedabad | D9: West | E9: Neha Gupta | F9: Both | G9: 2019
A10: STR09 | B10: Zomato - Jaipur Store | C10: Jaipur | D10: North | E10: Arjun Reddy | F10: Dine-in | G10: 2023
A11: STR10 | B11: Zomato - Lucknow Store | C11: Lucknow | D11: North | E11: Divya Menon | F11: Cloud Kitchen | G11: 2020
A12: STR11 | B12: Zomato - Chandigarh Store | C12: Chandigarh | D12: North | E12: Karan Malhotra | F12: Both | G12: 2022
A13: STR12 | B13: Zomato - Indore Store | C13: Indore | D13: Central | E13: Ritu Verma | F13: Dine-in | G13: 2018
